<?xml version="1.0"?>
<robot xmlns:xacro="http://www.ros.org/wiki/xacro" name="my_robot">

  <link name="base_link">
    <visual><geometry><box size="0.4 0.4 0.1"/></geometry></visual>
    <collision><geometry><box size="0.4 0.4 0.1"/></geometry></collision>
    <inertial>
      <mass value="5.0"/>
      <inertia ixx="0.07" ixy="0" ixz="0" iyy="0.07" iyz="0" izz="0.13"/>
    </inertial>
  </link>

  <link name="left_wheel">
    <visual><geometry><cylinder radius="0.1" length="0.05"/></geometry></visual>
    <collision><geometry><cylinder radius="0.1" length="0.05"/></geometry></collision>
    <inertial>
      <mass value="0.5"/>
      <inertia ixx="0.001" ixy="0" ixz="0" iyy="0.001" iyz="0" izz="0.002"/>
    </inertial>
  </link>

  <joint name="left_wheel_joint" type="continuous">
    <parent link="base_link"/><child link="left_wheel"/>
    <origin xyz="0 0.2 0" rpy="-1.5708 0 0"/><axis xyz="0 0 1"/>
  </joint>

  <link name="right_wheel">
    <visual><geometry><cylinder radius="0.1" length="0.05"/></geometry></visual>
    <collision><geometry><cylinder radius="0.1" length="0.05"/></geometry></collision>
    <inertial>
      <mass value="0.5"/>
      <inertia ixx="0.001" ixy="0" ixz="0" iyy="0.001" iyz="0" izz="0.002"/>
    </inertial>
  </link>

  <joint name="right_wheel_joint" type="continuous">
    <parent link="base_link"/><child link="right_wheel"/>
    <origin xyz="0 -0.2 0" rpy="-1.5708 0 0"/><axis xyz="0 0 1"/>
  </joint>

  <gazebo>
    <plugin name="differential_drive_controller" filename="libgazebo_ros_diff_drive.so">
      <updateRate>20</updateRate>
      <leftJoint>left_wheel_joint</leftJoint>
      <rightJoint>right_wheel_joint</rightJoint>
      <wheelSeparation>0.4</wheelSeparation>
      <wheelDiameter>0.2</wheelDiameter>
      <commandTopic>cmd_vel</commandTopic>
      <odometryTopic>odom</odometryTopic>
      <robotBaseFrame>base_link</robotBaseFrame>
      <publishWheelTF>true</publishWheelTF>
      <publishOdomTF>true</publishOdomTF>
    </plugin>
  </gazebo>

  <link name="lidar_link">
    <visual><geometry><cylinder radius="0.05" length="0.05"/></geometry></visual>
    <collision><geometry><cylinder radius="0.05" length="0.05"/></geometry></collision>
    <inertial>
      <mass value="0.1"/>
      <inertia ixx="0.0001" ixy="0" ixz="0" iyy="0.0001" iyz="0" izz="0.0001"/>
    </inertial>
  </link>

  <joint name="lidar_joint" type="fixed">
    <parent link="base_link"/><child link="lidar_link"/>
    <origin xyz="0.1 0 0.1" rpy="0 0 0"/>
  </joint>

  <gazebo reference="lidar_link">
    <sensor type="ray" name="laser">
      <visualize>false</visualize>
      <update_rate>40</update_rate>
      <ray>
        <scan><horizontal><samples>720</samples><resolution>1</resolution><min_angle>-3.14</min_angle><max_angle>3.14</max_angle></horizontal></scan>
        <range><min>0.30</min><max>30.0</max><resolution>0.01</resolution></range>
      </ray>
      <plugin name="gazebo_ros_laser_controller" filename="libgazebo_ros_laser.so">
        <topicName>/scan</topicName>
        <frameName>lidar_link</frameName>
      </plugin>
    </sensor>
  </gazebo>
</robot>
